<?xml version="1.0" encoding="UTF-8"?>

<root name="7dof_RISE" xmlns:xacro="http://ros.org/wiki/xacro">

  <xacro:macro name="default_material">
    <mu1>100000</mu1>
    <mu2>100000</mu2>
     <kp>100000000.0</kp>
     <kd>1.0</kd>
  </xacro:macro>

  
  <!-- MACRO FOR THE ROBOT ARM -->
  <xacro:macro name="RISE_7dof" params="parent mass_divider *origin">  
  	<joint name="7dof_RISE_base_footprint_joint" type="fixed">
	    <xacro:insert_block name="origin" />
	    <parent link="${parent}" />
	    <child link="7dof_RISE_base_footprint" />
    </joint>

  <link name="7dof_RISE_base_footprint"/>

  <joint name="7dof_RISE_base_joint" type="fixed">
    <parent link="7dof_RISE_base_footprint"/>
    <child link="7dof_RISE_base_link"/>
    <origin xyz="0.0 0.0 0" rpy="0 0 0"/>
  </joint>
   
  <link name="7dof_RISE_base_link">
  	<inertial>
      <origin xyz="0 0 0" rpy="0 0 0"/>
      <mass value="1"/>
      <inertia ixx="0.01" ixy="0.0" ixz="0.0"
               iyy="0.01" iyz="0.0"
               izz="0.01" />
    </inertial>
    <visual>
      <origin xyz="0 0 0.0" rpy="0 0 0"/>
      <geometry>
        <mesh filename="package://socialrobot_description/meshes/7dof_RISE/ASM0000_ASM.stl" scale="1 1 1"/>
      </geometry>
      <material name="light_black"/>
    </visual>
    <collision>
      <origin xyz="0 0 0.0" rpy="0 0 0"/>
      <geometry>
        <mesh filename="package://socialrobot_description/meshes/collision/7dof_RISE/ASM0000_ASM.stl" scale="1 1 1"/>
      </geometry>
    </collision>    
  </link>

  <joint name="7dof_RISE_joint_1" type="revolute">
    	<limit lower="-${60/180*M_PI}" upper="${240/180*M_PI}" effort="2.6" velocity="1.0" /> 
    <origin xyz="-0.011056 0.0019863 0.025041" rpy="0 0 -${M_PI_2}" />
        <parent link="7dof_RISE_base_link" />
        <child link="7dof_RISE_link_2" />
        <axis xyz="0 0 1"/>
  </joint>

  <link name="7dof_RISE_link_2">
    <inertial>
      <origin xyz="0 0 0" rpy="0 0 0"/>
      <mass value="1"/>
      <inertia ixx="0.01" ixy="0.0" ixz="0.0"
               iyy="0.01" iyz="0.0"
               izz="0.01" />
    </inertial>
    <visual>
      <origin xyz="0 0 0.0" rpy="0 0 0"/>
      <geometry>
        <mesh filename="package://socialrobot_description/meshes/7dof_RISE/ASM0001_ASM.stl" scale="1 1 1"/>
      </geometry>
      <material name="white"/>
    </visual>
    <collision>
      <origin xyz="0 0 0.0" rpy="0 0 0"/>
      <geometry>
        <mesh filename="package://socialrobot_description/meshes/collision/7dof_RISE/ASM0001_ASM.stl" scale="1 1 1"/>
      </geometry>
    </collision>    
  </link>

  <joint name="7dof_RISE_joint_2" type="revolute">
    <limit lower="-${45/180*M_PI}" upper="${135/180*M_PI}" effort="2.6" velocity="1.0" /> 
    <origin xyz="-0.00004742 0.00022442 0.095" rpy="-${M_PI_2} 0 0" />
        <parent link="7dof_RISE_link_2" />
        <child link="7dof_RISE_link_3" />
        <axis xyz="0 0 1"/>
  </joint>

  <link name="7dof_RISE_link_3">
    <inertial>
      <origin xyz="0 0 0" rpy="0 0 0"/>
      <mass value="1"/>
      <inertia ixx="0.01" ixy="0.0" ixz="0.0"
               iyy="0.01" iyz="0.0"
               izz="0.01" />
    </inertial>
    <visual>
      <origin xyz="0 0 0.0" rpy="0 0 0"/>
      <geometry>
        <mesh filename="package://socialrobot_description/meshes/7dof_RISE/ASM0002_ASM.stl" scale="1 1 1"/>
      </geometry>
      <material name="light_black"/>
    </visual>
    <collision>
      <origin xyz="0 0 0.0" rpy="0 0 0"/>
      <geometry>
        <mesh filename="package://socialrobot_description/meshes/collision/7dof_RISE/ASM0002_ASM.stl" scale="1 1 1"/>
      </geometry>
    </collision>    
  </link>

  <joint name="7dof_RISE_joint_3" type="revolute">
    <limit lower="-${45/180*M_PI}" upper="${135/180*M_PI}" effort="2.6" velocity="1.0" /> 
    <origin xyz="0 -0.236 0" rpy="${M_PI_2} -${M_PI_2} 0" />
        <parent link="7dof_RISE_link_3" />
        <child link="7dof_RISE_link_4" />
        <axis xyz="0 0 1"/>
  </joint>

  <link name="7dof_RISE_link_4">
    <inertial>
      <origin xyz="0 0 0" rpy="0 0 0"/>
      <mass value="1"/>
      <inertia ixx="0.01" ixy="0.0" ixz="0.0"
               iyy="0.01" iyz="0.0"
               izz="0.01" />
    </inertial>
    <visual>
      <origin xyz="0 0 0.0" rpy="0 0 0"/>
      <geometry>
        <mesh filename="package://socialrobot_description/meshes/7dof_RISE/ASM0003_ASM.stl" scale="1 1 1"/>
      </geometry>
      <material name="white"/>
    </visual>
    <collision>
      <origin xyz="0 0 0.0" rpy="0 0 0"/>
      <geometry>
        <mesh filename="package://socialrobot_description/meshes/collision/7dof_RISE/ASM0003_ASM.stl" scale="1 1 1"/>
      </geometry>
    </collision>    
  </link>

  <joint name="7dof_RISE_joint_4" type="revolute">
    <limit lower="0" upper="${145/180*M_PI}" effort="2.6" velocity="1.0" /> 
    <origin xyz="0 0 0" rpy="-${M_PI_2} 0 0" />
        <parent link="7dof_RISE_link_4" />
        <child link="7dof_RISE_link_5" />
        <axis xyz="0 0 1"/>
  </joint>

  <link name="7dof_RISE_link_5">
    <inertial>
      <origin xyz="0 0 0" rpy="0 0 0"/>
      <mass value="1"/>
      <inertia ixx="0.01" ixy="0.0" ixz="0.0"
               iyy="0.01" iyz="0.0"
               izz="0.01" />
    </inertial>
    <visual>
      <origin xyz="0 0 0.0" rpy="0 0 0"/>
      <geometry>
        <mesh filename="package://socialrobot_description/meshes/7dof_RISE/ASM0004_ASM.stl" scale="1 1 1"/>
      </geometry>
      <material name="light_black"/>
    </visual>
    <collision>
      <origin xyz="0 0 0.0" rpy="0 0 0"/>
      <geometry>
        <mesh filename="package://socialrobot_description/meshes/collision/7dof_RISE/ASM0004_ASM.stl" scale="1 1 1"/>
      </geometry>
    </collision>    
  </link>

  <joint name="7dof_RISE_joint_5" type="revolute">
    <limit lower="0" upper="${145/180*M_PI}" effort="2.6" velocity="1.0" /> 
    <origin xyz="0 -0.13603 0" rpy="${M_PI_2} ${M_PI_2} 0" />
        <parent link="7dof_RISE_link_5" />
        <child link="7dof_RISE_link_6" />
        <axis xyz="0 0 1"/>
  </joint>

  <link name="7dof_RISE_link_6">
    <inertial>
      <origin xyz="0 0 0" rpy="0 0 0"/>
      <mass value="1"/>
      <inertia ixx="0.01" ixy="0.0" ixz="0.0"
               iyy="0.01" iyz="0.0"
               izz="0.01" />
    </inertial>
    <visual>
      <origin xyz="0 0 0.0" rpy="0 0 0"/>
      <geometry>
        <mesh filename="package://socialrobot_description/meshes/7dof_RISE/ASM0005_ASM.stl" scale="1 1 1"/>
      </geometry>
      <material name="light_black"/>
    </visual>
    <collision>
      <origin xyz="0 0 0.0" rpy="0 0 0"/>
      <geometry>
        <mesh filename="package://socialrobot_description/meshes/collision/7dof_RISE/ASM0005_ASM.stl" scale="1 1 1"/>
      </geometry>
    </collision>    
  </link>

  <joint name="7dof_RISE_joint_6" type="revolute">
    <limit lower="0" upper="${145/180*M_PI}" effort="2.6" velocity="1.0" /> 
    <origin xyz="0 0 0.16" rpy="-${M_PI_2} ${M_PI_2} 0" />
        <parent link="7dof_RISE_link_6" />
        <child link="7dof_RISE_link_7" />
        <axis xyz="0 0 1"/>
  </joint>

  <link name="7dof_RISE_link_7">
    <inertial>
      <origin xyz="0 0 0" rpy="0 0 0"/>
      <mass value="1"/>
      <inertia ixx="0.01" ixy="0.0" ixz="0.0"
               iyy="0.01" iyz="0.0"
               izz="0.01" />
    </inertial>
    <visual>
      <origin xyz="0 0 0.0" rpy="0 0 0"/>
      <geometry>
        <mesh filename="package://socialrobot_description/meshes/7dof_RISE/ASM0006_ASM.stl" scale="1 1 1"/>
      </geometry>
      <material name="white"/>
    </visual>
    <collision>
      <origin xyz="0 0 0.0" rpy="0 0 0"/>
      <geometry>
        <mesh filename="package://socialrobot_description/meshes/collision/7dof_RISE/ASM0006_ASM.stl" scale="1 1 1"/>
      </geometry>
    </collision>    
  </link>

  <joint name="7dof_RISE_joint_7" type="revolute">
    <limit lower="0" upper="${145/180*M_PI}" effort="2.6" velocity="1.0" /> 
    <origin xyz="0 0 0" rpy="${M_PI_2} 0 0" />
        <parent link="7dof_RISE_link_7" />
        <child link="7dof_RISE_link_8" />
        <axis xyz="0 0 1"/>
  </joint>

  <link name="7dof_RISE_link_8">
    <inertial>
      <origin xyz="0 0 0" rpy="0 0 0"/>
      <mass value="1"/>
      <inertia ixx="0.01" ixy="0.0" ixz="0.0"
               iyy="0.01" iyz="0.0"
               izz="0.01" />
    </inertial>
    <visual>
      <origin xyz="0 0 0.0" rpy="0 0 0"/>
      <geometry>
        <mesh filename="package://socialrobot_description/meshes/7dof_RISE/ASM0007_ASM.stl" scale="1 1 1"/>
      </geometry>
      <material name="light_black"/>
    </visual>
    <collision>
      <origin xyz="0 0 0.0" rpy="0 0 0"/>
      <geometry>
        <mesh filename="package://socialrobot_description/meshes/collision/7dof_RISE/ASM0007_ASM.stl" scale="1 1 1"/>
      </geometry>
    </collision>    
  </link>

  <joint name="7dof_RISE_wrist_joint" type="fixed">
    <origin xyz="-0.08 0 0" rpy="-${M_PI_2} 0 ${M_PI_2}" />
        <parent link="7dof_RISE_link_8" />
        <child link="7dof_RISE_wrist_link" />
        <axis xyz="0 0 1"/>
  </joint>

  <link name="7dof_RISE_wrist_link"/>
  

  </xacro:macro>
</root>
