<?xml version="1.0" ?>
<!-- =================================================================================== -->
<!-- |    This document was autogenerated by xacro from urdf/socialrobot.urdf.xacro    | -->
<!-- |    EDITING THIS FILE BY HAND IS NOT RECOMMENDED                                 | -->
<!-- =================================================================================== -->
<robot name="socialrobot" xmlns:xacro="http://ros.org/wiki/xacro">
  <!-- Init colour -->
  <material name="black">
    <color rgba="0.0 0.0 0.0 1.0"/>
  </material>
  <material name="dark">
    <color rgba="0.3 0.3 0.3 1.0"/>
  </material>
  <material name="light_black">
    <color rgba="0.4 0.4 0.4 1.0"/>
  </material>
  <material name="blue">
    <color rgba="0.0 0.0 0.8 1.0"/>
  </material>
  <material name="green">
    <color rgba="0.0 0.8 0.0 1.0"/>
  </material>
  <material name="grey">
    <color rgba="0.5 0.5 0.5 1.0"/>
  </material>
  <material name="orange">
    <color rgba="1.0 0.423529411765 0.0392156862745 1.0"/>
  </material>
  <material name="brown">
    <color rgba="0.870588235294 0.811764705882 0.764705882353 1.0"/>
  </material>
  <material name="red">
    <color rgba="0.8 0.0 0.0 1.0"/>
  </material>
  <material name="white">
    <color rgba="1.0 1.0 1.0 1.0"/>
  </material>
  <link name="base_link">
  </link>
  <joint name="base_footprint_joint" type="fixed">
    <origin rpy="0 -1.57079632679 0" xyz="0 0 0.15"/>
    <parent link="base_link"/>
    <child link="body_frame"/>
  </joint>
  <link name="body_frame">
    <inertial>
      <origin rpy="0 0 0" xyz="0 0 0"/>
      <mass value="1"/>
      <inertia ixx="0.01" ixy="0.0" ixz="0.0" iyy="0.01" iyz="0.0" izz="0.01"/>
    </inertial>
    <visual>
      <origin rpy="0 0 0" xyz="0 0 0.0"/>
      <geometry>
        <mesh filename="package://socialrobot_description/meshes/mobile/base.stl" scale="1 1 1"/>
      </geometry>
      <material name="white"/>
    </visual>
    <collision>
      <origin rpy="0 0 0" xyz="0 0 0.0"/>
      <geometry>
        <mesh filename="package://socialrobot_description/meshes/mobile/base.stl" scale="1 1 1"/>
      </geometry>
    </collision>
  </link>
  <joint name="kinect_v2_base_footprint_joint" type="fixed">
    <origin rpy="0 1.57079632679 0" xyz="1.025 0 -0.05"/>
    <parent link="body_frame"/>
    <child link="kinect_v2_base_link"/>
  </joint>
  <link name="kinect_v2_base_link">
    <inertial>
      <origin rpy="0 0 0" xyz="0 0 0"/>
      <mass value="1"/>
      <inertia ixx="0.01" ixy="0.0" ixz="0.0" iyy="0.01" iyz="0.0" izz="0.01"/>
    </inertial>
    <visual>
      <origin rpy="0 0 0" xyz="0 0 0.0"/>
      <geometry>
        <mesh filename="package://socialrobot_description/meshes/kinect_v2/kienct_v2_base.stl" scale="1 1 1"/>
      </geometry>
      <material name="light_black"/>
    </visual>
    <collision>
      <origin rpy="0 0 0" xyz="0 0 0.0"/>
      <geometry>
        <mesh filename="package://socialrobot_description/meshes/kinect_v2/kienct_v2_base.stl" scale="1 1 1"/>
      </geometry>
    </collision>
  </link>
  <joint name="kinect_v2_base_joint" type="fixed">
    <parent link="kinect_v2_base_link"/>
    <child link="kinect_v2_body_link"/>
    <origin rpy="1.57079632679 -1.57079632679 0" xyz="0.0305 0 0.027"/>
  </joint>
  <link name="kinect_v2_body_link">
    <inertial>
      <origin rpy="0 0 0" xyz="0 0 0"/>
      <mass value="1"/>
      <inertia ixx="0.01" ixy="0.0" ixz="0.0" iyy="0.01" iyz="0.0" izz="0.01"/>
    </inertial>
    <visual>
      <origin rpy="0 0 0" xyz="0 0 0.0"/>
      <geometry>
        <mesh filename="package://socialrobot_description/meshes/kinect_v2/kinect_v2_body.stl" scale="1 1 1"/>
      </geometry>
      <material name="light_black"/>
    </visual>
    <collision>
      <origin rpy="0 0 0" xyz="0 0 0.0"/>
      <geometry>
        <mesh filename="package://socialrobot_description/meshes/kinect_v2/kinect_v2_body.stl" scale="1 1 1"/>
      </geometry>
    </collision>
  </link>
  <joint name="kinect_v2_rgb_joint" type="fixed">
    <parent link="kinect_v2_body_link"/>
    <child link="kinect_v2_rgb"/>
    <origin rpy="4.71238898038 0 -1.57079632679 " xyz="0.015964 -0.0095790 0.095008"/>
  </joint>
  <link name="kinect_v2_rgb"/>
  <joint name="kinect_v2_depth_joint" type="fixed">
    <parent link="kinect_v2_body_link"/>
    <child link="kinect_v2_depth"/>
    <origin rpy="4.71238898038 0 -1.57079632679 " xyz="0.015964 -0.0095790 0.095008"/>
  </joint>
  <link name="kinect_v2_depth"/>
  <joint name="6dof_RISE_base_footprint_joint" type="fixed">
    <origin rpy="1.57079632679 3.14159265359 0" xyz="0.8885 -0.14203 -0.0019477"/>
    <parent link="body_frame"/>
    <child link="6dof_RISE_base_footprint"/>
  </joint>
  <link name="6dof_RISE_base_footprint"/>
  <joint name="6dof_RISE_base_joint" type="fixed">
    <parent link="6dof_RISE_base_footprint"/>
    <child link="6dof_RISE_base_link"/>
    <origin rpy="-1.57079632679 -1.57079632679 0" xyz="0.0 0.0 0.062"/>
  </joint>
  <link name="6dof_RISE_base_link">
    <inertial>
      <origin rpy="0 0 0" xyz="0 0 0"/>
      <mass value="1"/>
      <inertia ixx="0.01" ixy="0.0" ixz="0.0" iyy="0.01" iyz="0.0" izz="0.01"/>
    </inertial>
    <visual>
      <origin rpy="0 0 0" xyz="0 0 0.0"/>
      <geometry>
        <mesh filename="package://socialrobot_description/meshes/6dof_RISE/6dof_1.stl" scale="1 1 1"/>
      </geometry>
      <material name="light_black"/>
    </visual>
    <collision>
      <origin rpy="0 0 0" xyz="0 0 0.0"/>
      <geometry>
        <mesh filename="package://socialrobot_description/meshes/6dof_RISE/6dof_1.stl" scale="1 1 1"/>
      </geometry>
    </collision>
  </link>
  <joint name="6dof_RISE_joint_1" type="revolute">
    <limit effort="2.6" lower="-1.57079632679" upper="3.14159265359" velocity="1.0"/>
    <origin rpy="0 1.57079632679 0" xyz="0.034 0 -0.033"/>
    <parent link="6dof_RISE_base_link"/>
    <child link="6dof_RISE_link_2"/>
    <axis xyz="0 0 1"/>
  </joint>
  <link name="6dof_RISE_link_2">
    <inertial>
      <origin rpy="0 0 0" xyz="0 0 0"/>
      <mass value="1"/>
      <inertia ixx="0.01" ixy="0.0" ixz="0.0" iyy="0.01" iyz="0.0" izz="0.01"/>
    </inertial>
    <visual>
      <origin rpy="0 0 0" xyz="0 0 0.0"/>
      <geometry>
        <mesh filename="package://socialrobot_description/meshes/6dof_RISE/6dof_2.stl" scale="1 1 1"/>
      </geometry>
      <material name="white"/>
    </visual>
    <collision>
      <origin rpy="0 0 0" xyz="0 0 0.0"/>
      <geometry>
        <mesh filename="package://socialrobot_description/meshes/6dof_RISE/6dof_2.stl" scale="1 1 1"/>
      </geometry>
    </collision>
  </link>
  <joint name="6dof_RISE_joint_2" type="revolute">
    <limit effort="2.6" lower="-1.57079632679" upper="3.14159265359" velocity="1.0"/>
    <origin rpy="1.57079632679 0 0" xyz="0.0051023 0 0.1655"/>
    <parent link="6dof_RISE_link_2"/>
    <child link="6dof_RISE_link_3"/>
    <axis xyz="0 0 1"/>
  </joint>
  <link name="6dof_RISE_link_3">
    <inertial>
      <origin rpy="0 0 0" xyz="0 0 0"/>
      <mass value="1"/>
      <inertia ixx="0.01" ixy="0.0" ixz="0.0" iyy="0.01" iyz="0.0" izz="0.01"/>
    </inertial>
    <visual>
      <origin rpy="0 0 0" xyz="0 0 0.0"/>
      <geometry>
        <mesh filename="package://socialrobot_description/meshes/6dof_RISE/6dof_3.stl" scale="1 1 1"/>
      </geometry>
      <material name="light_black"/>
    </visual>
    <collision>
      <origin rpy="0 0 0" xyz="0 0 0.0"/>
      <geometry>
        <mesh filename="package://socialrobot_description/meshes/6dof_RISE/6dof_3.stl" scale="1 1 1"/>
      </geometry>
    </collision>
  </link>
  <joint name="6dof_RISE_joint_3" type="revolute">
    <limit effort="2.6" lower="-2.09439510239" upper="4.18879020479" velocity="1.0"/>
    <origin rpy="-1.57079632679 0 0" xyz="0 0.11227 0"/>
    <parent link="6dof_RISE_link_3"/>
    <child link="6dof_RISE_link_4"/>
    <axis xyz="0 0 1"/>
  </joint>
  <link name="6dof_RISE_link_4">
    <inertial>
      <origin rpy="0 0 0" xyz="0 0 0"/>
      <mass value="1"/>
      <inertia ixx="0.01" ixy="0.0" ixz="0.0" iyy="0.01" iyz="0.0" izz="0.01"/>
    </inertial>
    <visual>
      <origin rpy="0 0 0" xyz="0 0 0.0"/>
      <geometry>
        <mesh filename="package://socialrobot_description/meshes/6dof_RISE/6dof_4.stl" scale="1 1 1"/>
      </geometry>
      <material name="white"/>
    </visual>
    <collision>
      <origin rpy="0 0 0" xyz="0 0 0.0"/>
      <geometry>
        <mesh filename="package://socialrobot_description/meshes/6dof_RISE/6dof_4.stl" scale="1 1 1"/>
      </geometry>
    </collision>
  </link>
  <joint name="6dof_RISE_joint_4" type="revolute">
    <limit effort="2.6" lower="-2.09439510239" upper="4.18879020479" velocity="1.0"/>
    <origin rpy="1.57079632679 0 0" xyz="0 0 0.26343"/>
    <parent link="6dof_RISE_link_4"/>
    <child link="6dof_RISE_link_5"/>
    <axis xyz="0 0 1"/>
  </joint>
  <link name="6dof_RISE_link_5">
    <inertial>
      <origin rpy="0 0 0" xyz="0 0 0"/>
      <mass value="1"/>
      <inertia ixx="0.01" ixy="0.0" ixz="0.0" iyy="0.01" iyz="0.0" izz="0.01"/>
    </inertial>
    <visual>
      <origin rpy="0 0 0" xyz="0 0 0.0"/>
      <geometry>
        <mesh filename="package://socialrobot_description/meshes/6dof_RISE/6dof_5.stl" scale="1 1 1"/>
      </geometry>
      <material name="white"/>
    </visual>
    <collision>
      <origin rpy="0 0 0" xyz="0 0 0.0"/>
      <geometry>
        <mesh filename="package://socialrobot_description/meshes/6dof_RISE/6dof_5.stl" scale="1 1 1"/>
      </geometry>
    </collision>
  </link>
  <joint name="6dof_RISE_joint_5" type="revolute">
    <limit effort="2.6" lower="-2.09439510239" upper="4.18879020479" velocity="1.0"/>
    <origin rpy="-1.57079632679 0 0" xyz="0 0.13911 0"/>
    <parent link="6dof_RISE_link_5"/>
    <child link="6dof_RISE_link_6"/>
    <axis xyz="0 0 1"/>
  </joint>
  <link name="6dof_RISE_link_6">
    <inertial>
      <origin rpy="0 0 0" xyz="0 0 0"/>
      <mass value="1"/>
      <inertia ixx="0.01" ixy="0.0" ixz="0.0" iyy="0.01" iyz="0.0" izz="0.01"/>
    </inertial>
    <visual>
      <origin rpy="0 0 0" xyz="0 0 0.0"/>
      <geometry>
        <mesh filename="package://socialrobot_description/meshes/6dof_RISE/6dof_6.stl" scale="1 1 1"/>
      </geometry>
      <material name="white"/>
    </visual>
    <collision>
      <origin rpy="0 0 0" xyz="0 0 0.0"/>
      <geometry>
        <mesh filename="package://socialrobot_description/meshes/6dof_RISE/6dof_6.stl" scale="1 1 1"/>
      </geometry>
    </collision>
  </link>
  <joint name="6dof_RISE_joint_6" type="revolute">
    <limit effort="2.6" lower="-2.09439510239" upper="4.18879020479" velocity="1.0"/>
    <origin rpy="1.57079632679 0 0" xyz="0 0 0.24709"/>
    <parent link="6dof_RISE_link_6"/>
    <child link="6dof_RISE_link_7"/>
    <axis xyz="0 0 1"/>
  </joint>
  <link name="6dof_RISE_link_7">
    <inertial>
      <origin rpy="0 0 0" xyz="0 0 0"/>
      <mass value="1"/>
      <inertia ixx="0.01" ixy="0.0" ixz="0.0" iyy="0.01" iyz="0.0" izz="0.01"/>
    </inertial>
    <visual>
      <origin rpy="0 0 0" xyz="0 0 0.0"/>
      <geometry>
        <mesh filename="package://socialrobot_description/meshes/6dof_RISE/6dof_7.stl" scale="1 1 1"/>
      </geometry>
      <material name="light_black"/>
    </visual>
    <collision>
      <origin rpy="0 0 0" xyz="0 0 0.0"/>
      <geometry>
        <mesh filename="package://socialrobot_description/meshes/6dof_RISE/6dof_7.stl" scale="1 1 1"/>
      </geometry>
    </collision>
  </link>
  <joint name="6dof_RISE_wrist_joint" type="fixed">
    <parent link="6dof_RISE_link_7"/>
    <child link="6dof_RISE_wrist_link"/>
    <origin rpy="-1.57079632679 0 0" xyz="0.00073845 0.057576 0.0047840"/>
  </joint>
  <link name="6dof_RISE_wrist_link"/>
  <!-- 7dof RISE manipulator -->
  <joint name="7dof_RISE_base_footprint_joint" type="fixed">
    <origin rpy="0 3.14159265359 -1.57079632679" xyz="0.88683 0.20797 -0.10595"/>
    <parent link="body_frame"/>
    <child link="7dof_RISE_base_footprint"/>
  </joint>
  <link name="7dof_RISE_base_footprint"/>
  <joint name="7dof_RISE_base_joint" type="fixed">
    <parent link="7dof_RISE_base_footprint"/>
    <child link="7dof_RISE_base_link"/>
    <origin rpy="0 0 0" xyz="0.0 0.0 0"/>
  </joint>
  <link name="7dof_RISE_base_link">
    <inertial>
      <origin rpy="0 0 0" xyz="0 0 0"/>
      <mass value="1"/>
      <inertia ixx="0.01" ixy="0.0" ixz="0.0" iyy="0.01" iyz="0.0" izz="0.01"/>
    </inertial>
    <visual>
      <origin rpy="0 0 0" xyz="0 0 0.0"/>
      <geometry>
        <mesh filename="package://socialrobot_description/meshes/7dof_RISE/ASM0000_ASM.stl" scale="1 1 1"/>
      </geometry>
      <material name="light_black"/>
    </visual>
    <collision>
      <origin rpy="0 0 0" xyz="0 0 0.0"/>
      <geometry>
        <mesh filename="package://socialrobot_description/meshes/7dof_RISE/ASM0000_ASM.stl" scale="1 1 1"/>
      </geometry>
    </collision>
  </link>
  <joint name="7dof_RISE_joint_1" type="revolute">
    <limit effort="2.6" lower="-1.0471975512" upper="4.18879020479" velocity="1.0"/>
    <origin rpy="0 0 -1.57079632679" xyz="-0.011056 0.0019863 0.025041"/>
    <parent link="7dof_RISE_base_link"/>
    <child link="7dof_RISE_link_2"/>
    <axis xyz="0 0 1"/>
  </joint>
  <link name="7dof_RISE_link_2">
    <inertial>
      <origin rpy="0 0 0" xyz="0 0 0"/>
      <mass value="1"/>
      <inertia ixx="0.01" ixy="0.0" ixz="0.0" iyy="0.01" iyz="0.0" izz="0.01"/>
    </inertial>
    <visual>
      <origin rpy="0 0 0" xyz="0 0 0.0"/>
      <geometry>
        <mesh filename="package://socialrobot_description/meshes/7dof_RISE/ASM0001_ASM.stl" scale="1 1 1"/>
      </geometry>
      <material name="white"/>
    </visual>
    <collision>
      <origin rpy="0 0 0" xyz="0 0 0.0"/>
      <geometry>
        <mesh filename="package://socialrobot_description/meshes/7dof_RISE/ASM0001_ASM.stl" scale="1 1 1"/>
      </geometry>
    </collision>
  </link>
  <joint name="7dof_RISE_joint_2" type="revolute">
    <limit effort="2.6" lower="-0.785398163397" upper="2.35619449019" velocity="1.0"/>
    <origin rpy="-1.57079632679 0 0" xyz="-0.00004742 0.00022442 0.095"/>
    <parent link="7dof_RISE_link_2"/>
    <child link="7dof_RISE_link_3"/>
    <axis xyz="0 0 1"/>
  </joint>
  <link name="7dof_RISE_link_3">
    <inertial>
      <origin rpy="0 0 0" xyz="0 0 0"/>
      <mass value="1"/>
      <inertia ixx="0.01" ixy="0.0" ixz="0.0" iyy="0.01" iyz="0.0" izz="0.01"/>
    </inertial>
    <visual>
      <origin rpy="0 0 0" xyz="0 0 0.0"/>
      <geometry>
        <mesh filename="package://socialrobot_description/meshes/7dof_RISE/ASM0002_ASM.stl" scale="1 1 1"/>
      </geometry>
      <material name="light_black"/>
    </visual>
    <collision>
      <origin rpy="0 0 0" xyz="0 0 0.0"/>
      <geometry>
        <mesh filename="package://socialrobot_description/meshes/7dof_RISE/ASM0002_ASM.stl" scale="1 1 1"/>
      </geometry>
    </collision>
  </link>
  <joint name="7dof_RISE_joint_3" type="revolute">
    <limit effort="2.6" lower="-0.785398163397" upper="2.35619449019" velocity="1.0"/>
    <origin rpy="1.57079632679 -1.57079632679 0" xyz="0 -0.236 0"/>
    <parent link="7dof_RISE_link_3"/>
    <child link="7dof_RISE_link_4"/>
    <axis xyz="0 0 1"/>
  </joint>
  <link name="7dof_RISE_link_4">
    <inertial>
      <origin rpy="0 0 0" xyz="0 0 0"/>
      <mass value="1"/>
      <inertia ixx="0.01" ixy="0.0" ixz="0.0" iyy="0.01" iyz="0.0" izz="0.01"/>
    </inertial>
    <visual>
      <origin rpy="0 0 0" xyz="0 0 0.0"/>
      <geometry>
        <mesh filename="package://socialrobot_description/meshes/7dof_RISE/ASM0003_ASM.stl" scale="1 1 1"/>
      </geometry>
      <material name="white"/>
    </visual>
    <collision>
      <origin rpy="0 0 0" xyz="0 0 0.0"/>
      <geometry>
        <mesh filename="package://socialrobot_description/meshes/7dof_RISE/ASM0003_ASM.stl" scale="1 1 1"/>
      </geometry>
    </collision>
  </link>
  <joint name="7dof_RISE_joint_4" type="revolute">
    <limit effort="2.6" lower="0" upper="2.53072741539" velocity="1.0"/>
    <origin rpy="-1.57079632679 0 0" xyz="0 0 0"/>
    <parent link="7dof_RISE_link_4"/>
    <child link="7dof_RISE_link_5"/>
    <axis xyz="0 0 1"/>
  </joint>
  <link name="7dof_RISE_link_5">
    <inertial>
      <origin rpy="0 0 0" xyz="0 0 0"/>
      <mass value="1"/>
      <inertia ixx="0.01" ixy="0.0" ixz="0.0" iyy="0.01" iyz="0.0" izz="0.01"/>
    </inertial>
    <visual>
      <origin rpy="0 0 0" xyz="0 0 0.0"/>
      <geometry>
        <mesh filename="package://socialrobot_description/meshes/7dof_RISE/ASM0004_ASM.stl" scale="1 1 1"/>
      </geometry>
      <material name="light_black"/>
    </visual>
    <collision>
      <origin rpy="0 0 0" xyz="0 0 0.0"/>
      <geometry>
        <mesh filename="package://socialrobot_description/meshes/7dof_RISE/ASM0004_ASM.stl" scale="1 1 1"/>
      </geometry>
    </collision>
  </link>
  <joint name="7dof_RISE_joint_5" type="revolute">
    <limit effort="2.6" lower="0" upper="2.53072741539" velocity="1.0"/>
    <origin rpy="1.57079632679 1.57079632679 0" xyz="0 -0.13603 0"/>
    <parent link="7dof_RISE_link_5"/>
    <child link="7dof_RISE_link_6"/>
    <axis xyz="0 0 1"/>
  </joint>
  <link name="7dof_RISE_link_6">
    <inertial>
      <origin rpy="0 0 0" xyz="0 0 0"/>
      <mass value="1"/>
      <inertia ixx="0.01" ixy="0.0" ixz="0.0" iyy="0.01" iyz="0.0" izz="0.01"/>
    </inertial>
    <visual>
      <origin rpy="0 0 0" xyz="0 0 0.0"/>
      <geometry>
        <mesh filename="package://socialrobot_description/meshes/7dof_RISE/ASM0005_ASM.stl" scale="1 1 1"/>
      </geometry>
      <material name="light_black"/>
    </visual>
    <collision>
      <origin rpy="0 0 0" xyz="0 0 0.0"/>
      <geometry>
        <mesh filename="package://socialrobot_description/meshes/7dof_RISE/ASM0005_ASM.stl" scale="1 1 1"/>
      </geometry>
    </collision>
  </link>
  <joint name="7dof_RISE_joint_6" type="revolute">
    <limit effort="2.6" lower="0" upper="2.53072741539" velocity="1.0"/>
    <origin rpy="-1.57079632679 1.57079632679 0" xyz="0 0 0.16"/>
    <parent link="7dof_RISE_link_6"/>
    <child link="7dof_RISE_link_7"/>
    <axis xyz="0 0 1"/>
  </joint>
  <link name="7dof_RISE_link_7">
    <inertial>
      <origin rpy="0 0 0" xyz="0 0 0"/>
      <mass value="1"/>
      <inertia ixx="0.01" ixy="0.0" ixz="0.0" iyy="0.01" iyz="0.0" izz="0.01"/>
    </inertial>
    <visual>
      <origin rpy="0 0 0" xyz="0 0 0.0"/>
      <geometry>
        <mesh filename="package://socialrobot_description/meshes/7dof_RISE/ASM0006_ASM.stl" scale="1 1 1"/>
      </geometry>
      <material name="white"/>
    </visual>
    <collision>
      <origin rpy="0 0 0" xyz="0 0 0.0"/>
      <geometry>
        <mesh filename="package://socialrobot_description/meshes/7dof_RISE/ASM0006_ASM.stl" scale="1 1 1"/>
      </geometry>
    </collision>
  </link>
  <joint name="7dof_RISE_joint_7" type="revolute">
    <limit effort="2.6" lower="0" upper="2.53072741539" velocity="1.0"/>
    <origin rpy="1.57079632679 0 0" xyz="0 0 0"/>
    <parent link="7dof_RISE_link_7"/>
    <child link="7dof_RISE_link_8"/>
    <axis xyz="0 0 1"/>
  </joint>
  <link name="7dof_RISE_link_8">
    <inertial>
      <origin rpy="0 0 0" xyz="0 0 0"/>
      <mass value="1"/>
      <inertia ixx="0.01" ixy="0.0" ixz="0.0" iyy="0.01" iyz="0.0" izz="0.01"/>
    </inertial>
    <visual>
      <origin rpy="0 0 0" xyz="0 0 0.0"/>
      <geometry>
        <mesh filename="package://socialrobot_description/meshes/7dof_RISE/ASM0007_ASM.stl" scale="1 1 1"/>
      </geometry>
      <material name="light_black"/>
    </visual>
    <collision>
      <origin rpy="0 0 0" xyz="0 0 0.0"/>
      <geometry>
        <mesh filename="package://socialrobot_description/meshes/7dof_RISE/ASM0007_ASM.stl" scale="1 1 1"/>
      </geometry>
    </collision>
  </link>
  <joint name="7dof_RISE_wrist_joint" type="fixed">
    <origin rpy="-1.57079632679 0 1.57079632679" xyz="-0.08 0 0"/>
    <parent link="7dof_RISE_link_8"/>
    <child link="7dof_RISE_wrist_link"/>
    <axis xyz="0 0 1"/>
  </joint>
  <link name="7dof_RISE_wrist_link"/>
  <joint name="left_bhand_base_footprint_joint" type="fixed">
    <origin rpy="0 0 3.14159265359" xyz="0 0 0"/>
    <parent link="6dof_RISE_wrist_link"/>
    <child link="left_bhand_base_link"/>
  </joint>
  <link name="left_bhand_base_link">
    <inertial>
      <origin rpy="0 0 0" xyz="-1.53444878605399E-05 -0.00277693660903533 0.0352882290973172"/>
      <mass value="0.377966381303299"/>
      <inertia ixx="0.000427326373018601" ixy="2.6443337984506E-07" ixz="-2.02908063714989E-07" iyy="0.000361316175967098" iyz="-3.0792687327603E-05" izz="0.000376798128588446"/>
    </inertial>
    <visual>
      <origin rpy="0 0 0" xyz="0 0 0"/>
      <geometry>
        <mesh filename="package://socialrobot_description/meshes/bhand_model/base_link.STL"/>
      </geometry>
      <material name="">
        <color rgba="0.752941176470588 0.752941176470588 0.752941176470588 1"/>
      </material>
    </visual>
    <collision>
      <origin rpy="0 0 0" xyz="0 0 0"/>
      <geometry>
        <mesh filename="package://socialrobot_description/meshes/bhand_model/base_link.STL"/>
      </geometry>
    </collision>
  </link>
  <link name="left_bhand_finger_1_prox_link">
    <inertial>
      <origin rpy="0 0 0" xyz="-0.0288648917008988 9.98379746692153E-05 0.0171253477569802"/>
      <mass value="56143.0626955765"/>
      <inertia ixx="10.4484040652085" ixy="-0.117861448219975" ixz="-5.31613760585343" iyy="33.9552353012776" iyz="0.0780041192837706" izz="29.3669090518615"/>
    </inertial>
    <visual>
      <origin rpy="0 0 0" xyz="0 0 0"/>
      <geometry>
        <mesh filename="package://socialrobot_description/meshes/bhand_model/finger_1_prox_link.STL"/>
      </geometry>
      <material name="">
        <color rgba="0.752941176470588 0.752941176470588 0.752941176470588 1"/>
      </material>
    </visual>
    <collision>
      <origin rpy="0 0 0" xyz="0 0 0"/>
      <geometry>
        <mesh filename="package://socialrobot_description/meshes/bhand_model/finger_1_prox_link.STL"/>
      </geometry>
    </collision>
  </link>
  <joint name="left_bhand_finger_1_prox_joint" type="revolute">
    <origin rpy="0 2.7051E-17 -1.5708" xyz="0.025 0 0.0415"/>
    <parent link="left_bhand_base_link"/>
    <child link="left_bhand_finger_1_prox_link"/>
    <axis xyz="0 0 1"/>
    <limit effort="0" lower="-3.141" upper="0" velocity="0"/>
  </joint>
  <link name="left_bhand_finger_1_med_liink">
    <inertial>
      <origin rpy="0 0 0" xyz="-0.030918176135544 0.0019693024932544 0.000743369842666108"/>
      <mass value="31321.1214212939"/>
      <inertia ixx="2.18512832127284" ixy="-0.844484268309696" ixz="0.0135401272401385" iyy="17.3596441998536" iyz="-0.001126692167519" izz="17.7656644395659"/>
    </inertial>
    <visual>
      <origin rpy="0 0 0" xyz="0 0 0"/>
      <geometry>
        <mesh filename="package://socialrobot_description/meshes/bhand_model/finger_1_med_liink.STL"/>
      </geometry>
      <material name="">
        <color rgba="0.752941176470588 0.752941176470588 0.752941176470588 1"/>
      </material>
    </visual>
    <collision>
      <origin rpy="0 0 0" xyz="0 0 0"/>
      <geometry>
        <mesh filename="package://socialrobot_description/meshes/bhand_model/finger_1_med_liink.STL"/>
      </geometry>
    </collision>
  </link>
  <joint name="left_bhand_finger_1_med_joint" type="revolute">
    <origin rpy="1.5708 -8.8281E-17 0" xyz="-0.05 0 0.0339"/>
    <parent link="left_bhand_finger_1_prox_link"/>
    <child link="left_bhand_finger_1_med_liink"/>
    <axis xyz="0 0 1"/>
    <limit effort="0" lower="-2.44" upper="0" velocity="0"/>
  </joint>
  <link name="left_bhand_finger_1_dist_link">
    <inertial>
      <origin rpy="0 0 0" xyz="-0.018331495851456 0.017563370050582 0.000497127783315291"/>
      <mass value="19342.3312257343"/>
      <inertia ixx="3.67466110522623" ixy="-2.57800680786605" ixz="-0.0345727635031181" iyy="4.08727012680705" iyz="0.0329223427372985" izz="5.99395386650428"/>
    </inertial>
    <visual>
      <origin rpy="0 0 0" xyz="0 0 0"/>
      <geometry>
        <mesh filename="package://socialrobot_description/meshes/bhand_model/finger_1_dist_link.STL"/>
      </geometry>
      <material name="">
        <color rgba="0.898039215686275 0.917647058823529 0.929411764705882 1"/>
      </material>
    </visual>
    <collision>
      <origin rpy="0 0 0" xyz="0 0 0"/>
      <geometry>
        <mesh filename="package://socialrobot_description/meshes/bhand_model/finger_1_dist_link.STL"/>
      </geometry>
    </collision>
  </link>
  <joint name="left_bhand_finger_1_dist_joint" type="revolute">
    <origin rpy="1.6787E-18 -3.6382E-15 -6.1073E-33" xyz="-0.069936 0.003 0"/>
    <parent link="left_bhand_finger_1_med_liink"/>
    <child link="left_bhand_finger_1_dist_link"/>
    <axis xyz="0 0 1"/>
    <limit effort="0" lower="-0.785" upper="0" velocity="0"/>
  </joint>
  <link name="left_bhand_finger_2_prox_link">
    <inertial>
      <origin rpy="0 0 0" xyz="-0.0288648917008987 9.98379746692118E-05 0.0171253477569802"/>
      <mass value="56143.0626955765"/>
      <inertia ixx="10.4484040652085" ixy="-0.117861448219975" ixz="-5.31613760585343" iyy="33.9552353012776" iyz="0.0780041192837701" izz="29.3669090518615"/>
    </inertial>
    <visual>
      <origin rpy="0 0 0" xyz="0 0 0"/>
      <geometry>
        <mesh filename="package://socialrobot_description/meshes/bhand_model/finger_2_prox_link.STL"/>
      </geometry>
      <material name="">
        <color rgba="0.752941176470588 0.752941176470588 0.752941176470588 1"/>
      </material>
    </visual>
    <collision>
      <origin rpy="0 0 0" xyz="0 0 0"/>
      <geometry>
        <mesh filename="package://socialrobot_description/meshes/bhand_model/finger_2_prox_link.STL"/>
      </geometry>
    </collision>
  </link>
  <joint name="left_bhand_finger_2_prox_joint" type="revolute">
    <origin rpy="0 2.7051E-17 -1.5708" xyz="-0.025 0 0.0415"/>
    <parent link="left_bhand_base_link"/>
    <child link="left_bhand_finger_2_prox_link"/>
    <axis xyz="0 0 1"/>
    <limit effort="0" lower="0" upper="3.141" velocity="0"/>
  </joint>
  <link name="left_bhand_finger_2_med_link">
    <inertial>
      <origin rpy="0 0 0" xyz="-0.0309061378225848 0.00214997948654991 0.000743369814045599"/>
      <mass value="31321.1215499126"/>
      <inertia ixx="2.19551825824831" ixy="-0.933117181988174" ixz="0.0135333166873642" iyy="17.3492542935561" iyz="-0.00120585854514789" izz="17.7656644132238"/>
    </inertial>
    <visual>
      <origin rpy="0 0 0" xyz="0 0 0"/>
      <geometry>
        <mesh filename="package://socialrobot_description/meshes/bhand_model/finger_2_med_link.STL"/>
      </geometry>
      <material name="">
        <color rgba="0.752941176470588 0.752941176470588 0.752941176470588 1"/>
      </material>
    </visual>
    <collision>
      <origin rpy="0 0 0" xyz="0 0 0"/>
      <geometry>
        <mesh filename="package://socialrobot_description/meshes/bhand_model/finger_2_med_link.STL"/>
      </geometry>
    </collision>
  </link>
  <joint name="left_bhand_finger_2_med_joint" type="revolute">
    <origin rpy="1.5708 -8.8281E-17 0" xyz="-0.05 0 0.0339"/>
    <parent link="left_bhand_finger_2_prox_link"/>
    <child link="left_bhand_finger_2_med_link"/>
    <axis xyz="0 0 1"/>
    <limit effort="0" lower="-2.44" upper="0" velocity="0"/>
  </joint>
  <link name="left_bhand_finger_2_dist_link">
    <inertial>
      <origin rpy="0 0 0" xyz="-0.0181940669984822 0.017705695005231 0.000497127783261171"/>
      <mass value="19342.3313295693"/>
      <inertia ixx="3.71486604025429" ixy="-2.58090906930852" ixz="-0.0343151446338957" iyy="4.04706522522361" iyz="0.0331907761165059" izz="5.99395390717116"/>
    </inertial>
    <visual>
      <origin rpy="0 0 0" xyz="0 0 0"/>
      <geometry>
        <mesh filename="package://socialrobot_description/meshes/bhand_model/finger_2_dist_link.STL"/>
      </geometry>
      <material name="">
        <color rgba="0.898039215686275 0.917647058823529 0.929411764705882 1"/>
      </material>
    </visual>
    <collision>
      <origin rpy="0 0 0" xyz="0 0 0"/>
      <geometry>
        <mesh filename="package://socialrobot_description/meshes/bhand_model/finger_2_dist_link.STL"/>
      </geometry>
    </collision>
  </link>
  <joint name="left_bhand_finger_2_dist_joint" type="revolute">
    <origin rpy="-3.1382E-17 -2.3229E-16 0" xyz="-0.069917 0.0034087 0"/>
    <parent link="left_bhand_finger_2_med_link"/>
    <child link="left_bhand_finger_2_dist_link"/>
    <axis xyz="0 0 1"/>
    <limit effort="0" lower="-0.785" upper="0" velocity="0"/>
  </joint>
  <link name="left_bhand_finger_3_med_link">
    <inertial>
      <origin rpy="0 0 0" xyz="-0.0309181761355441 0.00196930249325443 0.000743369842666415"/>
      <mass value="31321.121421294"/>
      <inertia ixx="2.18512832127284" ixy="-0.844484268309696" ixz="0.0135401272400822" iyy="17.3596441998537" iyz="-0.0011266921675151" izz="17.7656644395659"/>
    </inertial>
    <visual>
      <origin rpy="0 0 0" xyz="0 0 0"/>
      <geometry>
        <mesh filename="package://socialrobot_description/meshes/bhand_model/finger_3_med_link.STL"/>
      </geometry>
      <material name="">
        <color rgba="0.752941176470588 0.752941176470588 0.752941176470588 1"/>
      </material>
    </visual>
    <collision>
      <origin rpy="0 0 0" xyz="0 0 0"/>
      <geometry>
        <mesh filename="package://socialrobot_description/meshes/bhand_model/finger_3_med_link.STL"/>
      </geometry>
    </collision>
  </link>
  <joint name="left_bhand_finger_3_med_joint" type="revolute">
    <origin rpy="1.5708 6.123E-17 1.5708" xyz="0 -0.05 0.0754"/>
    <parent link="left_bhand_base_link"/>
    <child link="left_bhand_finger_3_med_link"/>
    <axis xyz="0 0 1"/>
    <limit effort="0" lower="-2.44" upper="0" velocity="0"/>
  </joint>
  <link name="left_bhand_finger_3_dist_link">
    <inertial>
      <origin rpy="0 0 0" xyz="-0.0183314958518909 0.0175633700501297 0.000497127783323787"/>
      <mass value="19342.3312257343"/>
      <inertia ixx="3.67466110509902" ixy="-2.57800680785588" ixz="-0.0345727635040649" iyy="4.08727012693427" iyz="0.0329223427365976" izz="5.99395386650428"/>
    </inertial>
    <visual>
      <origin rpy="0 0 0" xyz="0 0 0"/>
      <geometry>
        <mesh filename="package://socialrobot_description/meshes/bhand_model/finger_3_dist_link.STL"/>
      </geometry>
      <material name="">
        <color rgba="0.898039215686275 0.917647058823529 0.929411764705882 1"/>
      </material>
    </visual>
    <collision>
      <origin rpy="0 0 0" xyz="0 0 0"/>
      <geometry>
        <mesh filename="package://socialrobot_description/meshes/bhand_model/finger_3_dist_link.STL"/>
      </geometry>
    </collision>
  </link>
  <joint name="left_bhand_finger_3_dist_joint" type="revolute">
    <origin rpy="6.0427E-17 -6.7283E-18 -4.0657E-34" xyz="-0.069936 0.003 0"/>
    <parent link="left_bhand_finger_3_med_link"/>
    <child link="left_bhand_finger_3_dist_link"/>
    <axis xyz="0 0 1"/>
    <limit effort="0" lower="-0.785" upper="0" velocity="0"/>
  </joint>
  <joint name="right_bhand_base_footprint_joint" type="fixed">
    <origin rpy="0 0 0" xyz="0 0 0"/>
    <parent link="7dof_RISE_wrist_link"/>
    <child link="right_bhand_base_link"/>
  </joint>
  <link name="right_bhand_base_link">
    <inertial>
      <origin rpy="0 0 0" xyz="-1.53444878605399E-05 -0.00277693660903533 0.0352882290973172"/>
      <mass value="0.377966381303299"/>
      <inertia ixx="0.000427326373018601" ixy="2.6443337984506E-07" ixz="-2.02908063714989E-07" iyy="0.000361316175967098" iyz="-3.0792687327603E-05" izz="0.000376798128588446"/>
    </inertial>
    <visual>
      <origin rpy="0 0 0" xyz="0 0 0"/>
      <geometry>
        <mesh filename="package://socialrobot_description/meshes/bhand_model/base_link.STL"/>
      </geometry>
      <material name="">
        <color rgba="0.752941176470588 0.752941176470588 0.752941176470588 1"/>
      </material>
    </visual>
    <collision>
      <origin rpy="0 0 0" xyz="0 0 0"/>
      <geometry>
        <mesh filename="package://socialrobot_description/meshes/bhand_model/base_link.STL"/>
      </geometry>
    </collision>
  </link>
  <link name="right_bhand_finger_1_prox_link">
    <inertial>
      <origin rpy="0 0 0" xyz="-0.0288648917008988 9.98379746692153E-05 0.0171253477569802"/>
      <mass value="56143.0626955765"/>
      <inertia ixx="10.4484040652085" ixy="-0.117861448219975" ixz="-5.31613760585343" iyy="33.9552353012776" iyz="0.0780041192837706" izz="29.3669090518615"/>
    </inertial>
    <visual>
      <origin rpy="0 0 0" xyz="0 0 0"/>
      <geometry>
        <mesh filename="package://socialrobot_description/meshes/bhand_model/finger_1_prox_link.STL"/>
      </geometry>
      <material name="">
        <color rgba="0.752941176470588 0.752941176470588 0.752941176470588 1"/>
      </material>
    </visual>
    <collision>
      <origin rpy="0 0 0" xyz="0 0 0"/>
      <geometry>
        <mesh filename="package://socialrobot_description/meshes/bhand_model/finger_1_prox_link.STL"/>
      </geometry>
    </collision>
  </link>
  <joint name="right_bhand_finger_1_prox_joint" type="revolute">
    <origin rpy="0 2.7051E-17 -1.5708" xyz="0.025 0 0.0415"/>
    <parent link="right_bhand_base_link"/>
    <child link="right_bhand_finger_1_prox_link"/>
    <axis xyz="0 0 1"/>
    <limit effort="0" lower="-3.141" upper="0" velocity="0"/>
  </joint>
  <link name="right_bhand_finger_1_med_liink">
    <inertial>
      <origin rpy="0 0 0" xyz="-0.030918176135544 0.0019693024932544 0.000743369842666108"/>
      <mass value="31321.1214212939"/>
      <inertia ixx="2.18512832127284" ixy="-0.844484268309696" ixz="0.0135401272401385" iyy="17.3596441998536" iyz="-0.001126692167519" izz="17.7656644395659"/>
    </inertial>
    <visual>
      <origin rpy="0 0 0" xyz="0 0 0"/>
      <geometry>
        <mesh filename="package://socialrobot_description/meshes/bhand_model/finger_1_med_liink.STL"/>
      </geometry>
      <material name="">
        <color rgba="0.752941176470588 0.752941176470588 0.752941176470588 1"/>
      </material>
    </visual>
    <collision>
      <origin rpy="0 0 0" xyz="0 0 0"/>
      <geometry>
        <mesh filename="package://socialrobot_description/meshes/bhand_model/finger_1_med_liink.STL"/>
      </geometry>
    </collision>
  </link>
  <joint name="right_bhand_finger_1_med_joint" type="revolute">
    <origin rpy="1.5708 -8.8281E-17 0" xyz="-0.05 0 0.0339"/>
    <parent link="right_bhand_finger_1_prox_link"/>
    <child link="right_bhand_finger_1_med_liink"/>
    <axis xyz="0 0 1"/>
    <limit effort="0" lower="-2.44" upper="0" velocity="0"/>
  </joint>
  <link name="right_bhand_finger_1_dist_link">
    <inertial>
      <origin rpy="0 0 0" xyz="-0.018331495851456 0.017563370050582 0.000497127783315291"/>
      <mass value="19342.3312257343"/>
      <inertia ixx="3.67466110522623" ixy="-2.57800680786605" ixz="-0.0345727635031181" iyy="4.08727012680705" iyz="0.0329223427372985" izz="5.99395386650428"/>
    </inertial>
    <visual>
      <origin rpy="0 0 0" xyz="0 0 0"/>
      <geometry>
        <mesh filename="package://socialrobot_description/meshes/bhand_model/finger_1_dist_link.STL"/>
      </geometry>
      <material name="">
        <color rgba="0.898039215686275 0.917647058823529 0.929411764705882 1"/>
      </material>
    </visual>
    <collision>
      <origin rpy="0 0 0" xyz="0 0 0"/>
      <geometry>
        <mesh filename="package://socialrobot_description/meshes/bhand_model/finger_1_dist_link.STL"/>
      </geometry>
    </collision>
  </link>
  <joint name="right_bhand_finger_1_dist_joint" type="revolute">
    <origin rpy="1.6787E-18 -3.6382E-15 -6.1073E-33" xyz="-0.069936 0.003 0"/>
    <parent link="right_bhand_finger_1_med_liink"/>
    <child link="right_bhand_finger_1_dist_link"/>
    <axis xyz="0 0 1"/>
    <limit effort="0" lower="-0.785" upper="0" velocity="0"/>
  </joint>
  <link name="right_bhand_finger_2_prox_link">
    <inertial>
      <origin rpy="0 0 0" xyz="-0.0288648917008987 9.98379746692118E-05 0.0171253477569802"/>
      <mass value="56143.0626955765"/>
      <inertia ixx="10.4484040652085" ixy="-0.117861448219975" ixz="-5.31613760585343" iyy="33.9552353012776" iyz="0.0780041192837701" izz="29.3669090518615"/>
    </inertial>
    <visual>
      <origin rpy="0 0 0" xyz="0 0 0"/>
      <geometry>
        <mesh filename="package://socialrobot_description/meshes/bhand_model/finger_2_prox_link.STL"/>
      </geometry>
      <material name="">
        <color rgba="0.752941176470588 0.752941176470588 0.752941176470588 1"/>
      </material>
    </visual>
    <collision>
      <origin rpy="0 0 0" xyz="0 0 0"/>
      <geometry>
        <mesh filename="package://socialrobot_description/meshes/bhand_model/finger_2_prox_link.STL"/>
      </geometry>
    </collision>
  </link>
  <joint name="right_bhand_finger_2_prox_joint" type="revolute">
    <origin rpy="0 2.7051E-17 -1.5708" xyz="-0.025 0 0.0415"/>
    <parent link="right_bhand_base_link"/>
    <child link="right_bhand_finger_2_prox_link"/>
    <axis xyz="0 0 1"/>
    <limit effort="0" lower="0" upper="3.141" velocity="0"/>
  </joint>
  <link name="right_bhand_finger_2_med_link">
    <inertial>
      <origin rpy="0 0 0" xyz="-0.0309061378225848 0.00214997948654991 0.000743369814045599"/>
      <mass value="31321.1215499126"/>
      <inertia ixx="2.19551825824831" ixy="-0.933117181988174" ixz="0.0135333166873642" iyy="17.3492542935561" iyz="-0.00120585854514789" izz="17.7656644132238"/>
    </inertial>
    <visual>
      <origin rpy="0 0 0" xyz="0 0 0"/>
      <geometry>
        <mesh filename="package://socialrobot_description/meshes/bhand_model/finger_2_med_link.STL"/>
      </geometry>
      <material name="">
        <color rgba="0.752941176470588 0.752941176470588 0.752941176470588 1"/>
      </material>
    </visual>
    <collision>
      <origin rpy="0 0 0" xyz="0 0 0"/>
      <geometry>
        <mesh filename="package://socialrobot_description/meshes/bhand_model/finger_2_med_link.STL"/>
      </geometry>
    </collision>
  </link>
  <joint name="right_bhand_finger_2_med_joint" type="revolute">
    <origin rpy="1.5708 -8.8281E-17 0" xyz="-0.05 0 0.0339"/>
    <parent link="right_bhand_finger_2_prox_link"/>
    <child link="right_bhand_finger_2_med_link"/>
    <axis xyz="0 0 1"/>
    <limit effort="0" lower="-2.44" upper="0" velocity="0"/>
  </joint>
  <link name="right_bhand_finger_2_dist_link">
    <inertial>
      <origin rpy="0 0 0" xyz="-0.0181940669984822 0.017705695005231 0.000497127783261171"/>
      <mass value="19342.3313295693"/>
      <inertia ixx="3.71486604025429" ixy="-2.58090906930852" ixz="-0.0343151446338957" iyy="4.04706522522361" iyz="0.0331907761165059" izz="5.99395390717116"/>
    </inertial>
    <visual>
      <origin rpy="0 0 0" xyz="0 0 0"/>
      <geometry>
        <mesh filename="package://socialrobot_description/meshes/bhand_model/finger_2_dist_link.STL"/>
      </geometry>
      <material name="">
        <color rgba="0.898039215686275 0.917647058823529 0.929411764705882 1"/>
      </material>
    </visual>
    <collision>
      <origin rpy="0 0 0" xyz="0 0 0"/>
      <geometry>
        <mesh filename="package://socialrobot_description/meshes/bhand_model/finger_2_dist_link.STL"/>
      </geometry>
    </collision>
  </link>
  <joint name="right_bhand_finger_2_dist_joint" type="revolute">
    <origin rpy="-3.1382E-17 -2.3229E-16 0" xyz="-0.069917 0.0034087 0"/>
    <parent link="right_bhand_finger_2_med_link"/>
    <child link="right_bhand_finger_2_dist_link"/>
    <axis xyz="0 0 1"/>
    <limit effort="0" lower="-0.785" upper="0" velocity="0"/>
  </joint>
  <link name="right_bhand_finger_3_med_link">
    <inertial>
      <origin rpy="0 0 0" xyz="-0.0309181761355441 0.00196930249325443 0.000743369842666415"/>
      <mass value="31321.121421294"/>
      <inertia ixx="2.18512832127284" ixy="-0.844484268309696" ixz="0.0135401272400822" iyy="17.3596441998537" iyz="-0.0011266921675151" izz="17.7656644395659"/>
    </inertial>
    <visual>
      <origin rpy="0 0 0" xyz="0 0 0"/>
      <geometry>
        <mesh filename="package://socialrobot_description/meshes/bhand_model/finger_3_med_link.STL"/>
      </geometry>
      <material name="">
        <color rgba="0.752941176470588 0.752941176470588 0.752941176470588 1"/>
      </material>
    </visual>
    <collision>
      <origin rpy="0 0 0" xyz="0 0 0"/>
      <geometry>
        <mesh filename="package://socialrobot_description/meshes/bhand_model/finger_3_med_link.STL"/>
      </geometry>
    </collision>
  </link>
  <joint name="right_bhand_finger_3_med_joint" type="revolute">
    <origin rpy="1.5708 6.123E-17 1.5708" xyz="0 -0.05 0.0754"/>
    <parent link="right_bhand_base_link"/>
    <child link="right_bhand_finger_3_med_link"/>
    <axis xyz="0 0 1"/>
    <limit effort="0" lower="-2.44" upper="0" velocity="0"/>
  </joint>
  <link name="right_bhand_finger_3_dist_link">
    <inertial>
      <origin rpy="0 0 0" xyz="-0.0183314958518909 0.0175633700501297 0.000497127783323787"/>
      <mass value="19342.3312257343"/>
      <inertia ixx="3.67466110509902" ixy="-2.57800680785588" ixz="-0.0345727635040649" iyy="4.08727012693427" iyz="0.0329223427365976" izz="5.99395386650428"/>
    </inertial>
    <visual>
      <origin rpy="0 0 0" xyz="0 0 0"/>
      <geometry>
        <mesh filename="package://socialrobot_description/meshes/bhand_model/finger_3_dist_link.STL"/>
      </geometry>
      <material name="">
        <color rgba="0.898039215686275 0.917647058823529 0.929411764705882 1"/>
      </material>
    </visual>
    <collision>
      <origin rpy="0 0 0" xyz="0 0 0"/>
      <geometry>
        <mesh filename="package://socialrobot_description/meshes/bhand_model/finger_3_dist_link.STL"/>
      </geometry>
    </collision>
  </link>
  <joint name="right_bhand_finger_3_dist_joint" type="revolute">
    <origin rpy="6.0427E-17 -6.7283E-18 -4.0657E-34" xyz="-0.069936 0.003 0"/>
    <parent link="right_bhand_finger_3_med_link"/>
    <child link="right_bhand_finger_3_dist_link"/>
    <axis xyz="0 0 1"/>
    <limit effort="0" lower="-0.785" upper="0" velocity="0"/>
  </joint>
</robot>

